File: Data Analysis Automation Apps/Compression/compliance_edit.csv
Test Method,Test Method,,
Sample I. D.,Material and Date,,
Specimen Number,1,,
,,,
Time (min),Load (N),% Compression (%),Crosshead (mil)
,,,
0.001,-0.007,0.394,0.9961
0.002,0.013,0.787,0.9921
0.003,-0.001,1.181,0.9882
0.003,-0.001,1.575,0.9843
0.004,-0.007,1.968,0.9803
0.005,-0.001,2.362,0.9764
0.005,0.018,3.15,0.9685
0.006,0.004,3.543,0.9646
0.007,-0.005,4.331,0.9567
0.007,0,4.724,0.9528
0.008,0.007,5.118,0.9488
0.009,-0.011,5.905,0.9409
0.009,0.006,6.299,0.937
0.01,0.002,7.087,0.9291
0.011,0.011,7.48,0.9252
0.011,-0.009,8.268,0.9173
0.012,-0.022,8.661,0.9134
0.013,-0.006,9.449,0.9055
0.013,0.007,9.842,0.9016
0.014,0.012,10.63,0.8937
0.015,0.008,11.417,0.8858
0.015,0,11.811,0.8819
0.016,0.009,12.598,0.874
0.017,-0.006,12.992,0.8701
0.017,0.011,13.779,0.8622
0.018,-0.001,14.567,0.8543
0.019,-0.012,14.961,0.8504
0.019,0.003,15.748,0.8425
0.02,-0.011,16.535,0.8346
0.021,-0.009,16.929,0.8307
0.021,0.003,17.716,0.8228
0.022,-0.005,18.504,0.815
0.023,0.005,18.898,0.811
0.023,-0.002,19.685,0.8032
0.024,-0.008,20.079,0.7992
0.025,0.006,20.866,0.7913
0.025,0.006,21.654,0.7835
0.026,0.028,22.047,0.7795
0.027,0.002,22.835,0.7717
0.027,-0.004,23.228,0.7677
0.028,-0.016,24.016,0.7598
0.029,-0.007,24.803,0.752
0.029,-0.005,25.197,0.748
0.03,0.003,25.984,0.7402
0.031,0.002,26.772,0.7323
0.031,0.011,27.165,0.7283
0.032,-0.012,27.953,0.7205
0.033,-0.018,28.346,0.7165
0.033,0,29.134,0.7087
0.034,0.021,29.921,0.7008
0.035,0.006,30.315,0.6969
0.035,0.013,31.102,0.689
0.036,0.01,31.89,0.6811
0.037,0.011,32.283,0.6772
0.037,-0.01,33.071,0.6693
0.038,0.024,33.858,0.6614
0.039,0.011,34.252,0.6575
0.039,0.004,35.039,0.6496
0.04,0.009,35.827,0.6417
0.041,-0.012,36.22,0.6378
0.041,0.01,37.008,0.6299
0.042,-0.001,37.795,0.622
0.043,0.001,38.583,0.6142
0.043,0.008,38.976,0.6102
0.044,0.007,39.764,0.6024
0.045,0.006,40.551,0.5945
0.045,0.005,41.339,0.5866
0.046,0.002,42.126,0.5787
0.047,0.004,42.52,0.5748
0.047,-0.001,43.307,0.5669
0.048,-0.012,44.094,0.5591
0.049,0.002,44.882,0.5512
0.049,0.007,45.669,0.5433
0.05,0,46.063,0.5394
0.051,0.03,46.85,0.5315
0.051,0.013,47.638,0.5236
0.052,-0.016,48.425,0.5157
0.053,0.003,48.819,0.5118
0.053,-0.003,49.606,0.5039
0.054,-0.021,50.394,0.4961
0.055,0.015,50.787,0.4921
0.055,-0.009,51.575,0.4843
0.056,0.019,52.362,0.4764
0.057,0.002,52.756,0.4724
0.057,0.003,53.543,0.4646
0.058,0.008,54.331,0.4567
0.059,-0.017,54.724,0.4528
0.059,0.006,55.512,0.4449
0.06,0,56.299,0.437
0.061,0.006,56.693,0.4331
0.061,0.007,57.48,0.4252
0.062,0.003,58.268,0.4173
0.063,-0.007,58.661,0.4134
0.063,-0.006,59.449,0.4055
0.064,0.008,60.236,0.3976
0.065,-0.001,60.63,0.3937
0.065,0.013,61.417,0.3858
0.066,0.006,62.205,0.378
0.067,0.023,62.598,0.374
0.067,0.014,63.386,0.3661
0.068,0.02,64.173,0.3583
0.069,0,64.567,0.3543
0.069,0.012,65.354,0.3465
0.07,0.004,66.142,0.3386
0.071,0.004,66.535,0.3346
0.071,0.011,67.323,0.3268
0.072,0.005,68.11,0.3189
0.073,0.001,68.504,0.315
0.073,-0.006,69.291,0.3071
0.074,0.016,70.079,0.2992
0.075,-0.008,70.472,0.2953
0.075,0.008,71.26,0.2874
0.076,0.001,72.047,0.2795
0.077,0.006,72.441,0.2756
0.077,0.004,73.228,0.2677
0.078,0.019,74.016,0.2598
0.079,-0.014,74.409,0.2559
0.079,0.009,75.197,0.248
0.08,-0.005,75.984,0.2402
0.081,-0.001,76.772,0.2323
0.081,0.023,77.165,0.2283
0.082,0.02,77.953,0.2205
0.083,0.01,78.74,0.2126
0.083,0.004,79.134,0.2087
0.084,0.03,79.921,0.2008
0.085,0.004,80.315,0.1969
0.085,-0.009,81.102,0.189
0.086,-0.001,81.89,0.1811
0.087,0.015,82.283,0.1772
0.087,0.017,83.071,0.1693
0.088,0.043,83.858,0.1614
0.089,0.025,84.646,0.1535
0.089,0.027,85.039,0.1496
0.09,0.032,85.827,0.1417
0.091,0.033,86.22,0.1378
0.091,0.025,87.008,0.1299
0.092,0.06,87.795,0.122
0.093,0.04,88.189,0.1181
0.093,0.072,88.976,0.1102
0.094,0.049,89.764,0.1024
0.095,0.061,90.157,0.0984
0.095,0.068,90.945,0.0906
0.096,0.064,91.732,0.0827
0.097,0.056,92.126,0.0787
0.097,0.085,92.913,0.0709
0.098,0.069,93.701,0.063
0.099,0.051,94.094,0.0591
0.099,0.094,94.882,0.0512
0.1,0.067,95.669,0.0433
0.101,0.104,96.063,0.0394
0.101,0.087,96.85,0.0315
0.102,0.064,97.244,0.0276
0.103,0.129,98.031,0.0197
0.103,0.164,98.819,0.0118
0.104,0.229,99.606,0.0039
0.105,0.402,100,0
0.105,0.537,100.787,-0.0079
0.106,0.741,101.575,-0.0157
0.107,1.314,101.969,-0.0197
0.107,2.131,102.756,-0.0276
0.108,2.769,103.543,-0.0354
0.109,3.52,104.331,-0.0433
0.109,4.7,104.724,-0.0472
0.11,5.938,105.512,-0.0551
0.111,6.819,106.299,-0.063
0.111,8.051,107.087,-0.0709
0.112,9.431,107.48,-0.0748
0.113,10.743,108.268,-0.0827
0.113,12.164,109.055,-0.0906
0.114,13.668,109.843,-0.0984
0.115,14.871,110.63,-0.1063
0.115,16.364,111.024,-0.1102
0.116,17.789,111.811,-0.1181
0.117,19.097,111.811,-0.1181
0.117,23.09,113.386,-0.1339
0.118,24.146,114.173,-0.1417
0.119,25.445,114.567,-0.1457
0.119,26.84,115.354,-0.1535
0.12,28.079,116.142,-0.1614
0.121,29.643,116.535,-0.1654
0.121,31.394,117.323,-0.1732
0.122,32.355,118.11,-0.1811
0.123,33.888,118.504,-0.185
0.123,35.371,119.291,-0.1929
0.124,36.57,120.079,-0.2008
0.125,38.263,120.472,-0.2047
0.125,39.253,121.26,-0.2126
0.126,40.842,122.047,-0.2205
0.127,42.215,122.441,-0.2244
0.127,43.94,123.228,-0.2323
0.128,45.398,124.016,-0.2402
0.129,46.755,124.409,-0.2441
0.129,48.052,125.197,-0.252
0.13,49.371,125.984,-0.2598
0.131,51.275,126.378,-0.2638
0.131,52.579,127.165,-0.2717
0.132,53.825,127.559,-0.2756
0.133,55.489,128.346,-0.2835
0.133,56.821,129.134,-0.2913
0.134,58.248,129.528,-0.2953
0.135,59.967,130.315,-0.3031
0.135,61.144,131.102,-0.311
0.136,62.661,131.496,-0.315
0.137,64.104,132.283,-0.3228
0.137,65.39,133.071,-0.3307
0.138,66.901,133.465,-0.3346
0.139,68.618,134.252,-0.3425
0.139,69.786,135.039,-0.3504
0.14,71.286,135.433,-0.3543
0.141,72.537,136.22,-0.3622
0.141,73.964,137.008,-0.3701
0.142,75.539,137.402,-0.374
0.143,77.169,138.189,-0.3819
0.143,78.261,138.976,-0.3898
0.144,79.915,139.37,-0.3937
0.145,81.434,140.158,-0.4016
0.145,82.691,140.945,-0.4094
0.146,84.174,141.339,-0.4134
0.147,85.635,142.126,-0.4213
0.147,86.95,142.913,-0.4291
0.148,88.495,143.307,-0.4331
0.149,89.958,144.095,-0.4409
0.149,91.107,144.882,-0.4488
0.15,92.817,145.276,-0.4528
0.151,94.08,146.063,-0.4606
0.151,95.371,146.457,-0.4646
0.152,97.112,147.244,-0.4724
0.153,98.306,148.032,-0.4803
0.153,99.647,148.425,-0.4843
0.154,101.266,149.213,-0.4921
0.155,102.364,150,-0.5
0.155,103.927,150.394,-0.5039
0.156,105.352,151.181,-0.5118
0.157,106.399,151.969,-0.5197
0.157,107.919,152.362,-0.5236
0.158,109.351,153.15,-0.5315
0.159,110.609,153.937,-0.5394
0.159,111.945,154.331,-0.5433
0.16,113.253,155.118,-0.5512
0.161,114.579,155.512,-0.5551
0.161,116.271,156.299,-0.563
0.162,117.465,157.087,-0.5709
0.163,118.831,157.48,-0.5748
0.163,120.352,158.268,-0.5827
0.164,121.315,159.055,-0.5906
0.165,122.859,159.449,-0.5945
0.165,124.228,160.236,-0.6024
0.166,125.347,161.024,-0.6102
0.167,127.07,161.417,-0.6142
0.167,128.225,162.205,-0.622
0.168,129.435,162.992,-0.6299
0.169,130.888,163.386,-0.6339
0.169,132.226,164.173,-0.6417
0.17,133.508,164.961,-0.6496
0.171,135.037,165.354,-0.6535
0.171,136.435,166.142,-0.6614
0.172,137.432,166.929,-0.6693
0.173,139.039,167.323,-0.6732
0.173,140.364,168.11,-0.6811
0.174,141.537,168.898,-0.689
0.175,143.281,169.685,-0.6969
0.175,144.625,170.079,-0.7008
0.176,145.979,170.866,-0.7087
0.177,147.002,171.654,-0.7165
0.177,148.604,172.441,-0.7244
0.178,149.765,172.835,-0.7283
0.179,151.513,173.622,-0.7362
0.179,152.805,174.409,-0.7441
0.18,154.099,175.197,-0.752
0.181,155.634,175.591,-0.7559
0.181,157.037,176.378,-0.7638
0.182,158.537,177.165,-0.7717
0.183,159.582,177.953,-0.7795
0.183,160.948,178.74,-0.7874
0.184,162.363,179.134,-0.7913
0.185,163.815,179.921,-0.7992
0.185,164.853,180.709,-0.8071
0.186,165.999,181.102,-0.811
0.187,167.716,181.89,-0.8189
0.187,168.354,182.677,-0.8268
0.188,169.639,183.071,-0.8307
0.189,170.817,183.858,-0.8386
0.189,171.827,184.646,-0.8465
0.19,173.148,185.039,-0.8504
0.191,174.328,185.827,-0.8583
0.191,175.325,186.614,-0.8661
0.192,176.524,187.008,-0.8701
0.193,177.775,187.795,-0.878
0.193,178.759,188.583,-0.8858
0.194,179.97,188.976,-0.8898
0.195,181.19,189.764,-0.8976
0.195,182.019,190.551,-0.9055
0.196,183.466,190.945,-0.9094
0.197,184.526,191.732,-0.9173
0.197,185.419,192.52,-0.9252
0.198,186.77,192.913,-0.9291
0.199,187.821,193.701,-0.937
0.199,188.739,194.488,-0.9449
0.2,190.026,194.882,-0.9488
0.201,191.207,195.669,-0.9567
0.201,191.741,196.457,-0.9646
0.202,193.319,196.85,-0.9685
0.203,194.237,197.638,-0.9764
0.203,195.102,198.425,-0.9843
0.204,196.383,198.819,-0.9882
0.205,197.215,199.606,-0.9961
0.205,197.996,200.394,-1.0039
0.206,199.314,200.787,-1.0079
0.207,200.204,201.575,-1.0157
0.207,200.911,202.362,-1.0236
0.208,201.979,202.756,-1.0276
0.209,202.943,203.543,-1.0354
0.209,203.759,204.331,-1.0433
0.21,204.799,204.724,-1.0472
0.211,205.836,205.512,-1.0551
0.211,206.376,206.299,-1.063
0.212,207.396,206.693,-1.0669
0.213,208.314,207.48,-1.0748
0.213,209.02,208.268,-1.0827
0.214,209.894,208.661,-1.0866
0.215,210.847,209.449,-1.0945
0.215,211.457,210.236,-1.1024
0.216,212.223,210.63,-1.1063
0.217,213.358,211.417,-1.1142
0.217,213.994,212.205,-1.122
0.218,214.718,212.598,-1.126
0.219,215.807,213.386,-1.1339
0.219,216.421,214.173,-1.1417
0.22,217.29,214.567,-1.1457
0.221,218.258,215.354,-1.1535
0.221,218.782,216.142,-1.1614
0.222,219.788,216.535,-1.1654
0.223,220.613,217.323,-1.1732
0.223,221.174,218.11,-1.1811
0.224,222.058,218.504,-1.185
0.225,222.749,219.291,-1.1929
0.225,223.419,220.079,-1.2008
0.226,224.46,220.473,-1.2047
0.227,225.043,221.26,-1.2126
0.227,225.674,221.654,-1.2165
0.228,226.732,222.441,-1.2244
0.229,227.236,223.228,-1.2323
0.229,228.118,223.622,-1.2362
0.23,229.776,224.41,-1.2441
0.231,229.67,225.197,-1.252
0.231,230.707,225.591,-1.2559
0.232,231.247,226.378,-1.2638
0.233,231.838,226.772,-1.2677
0.233,233.001,227.559,-1.2756
0.234,233.452,228.347,-1.2835
0.235,234.213,228.74,-1.2874
0.235,235.149,229.528,-1.2953
0.236,235.668,230.315,-1.3032
0.237,236.68,230.709,-1.3071
0.237,237.71,231.496,-1.315
0.238,238.219,232.284,-1.3228
0.239,238.753,233.071,-1.3307
0.239,239.795,233.465,-1.3346
0.24,240.724,234.252,-1.3425
0.241,241.299,235.039,-1.3504
0.241,242.204,235.827,-1.3583
0.242,243.011,236.221,-1.3622
0.243,244.004,237.008,-1.3701
0.243,244.506,237.795,-1.378
0.244,245.305,238.583,-1.3858
0.245,246.279,238.976,-1.3898
0.245,247.154,239.764,-1.3976
0.246,248.105,240.551,-1.4055
0.247,249.025,241.339,-1.4134
0.247,249.683,242.126,-1.4213
0.248,250.35,242.913,-1.4291
0.249,251.274,243.307,-1.4331
0.249,252.098,244.095,-1.4409
0.25,252.836,244.882,-1.4488
0.251,253.281,245.669,-1.4567
0.251,254.206,246.063,-1.4606
0.252,255.056,246.85,-1.4685
0.253,255.582,247.638,-1.4764
0.253,256.378,248.425,-1.4843
0.254,257.154,248.819,-1.4882
0.255,257.583,249.606,-1.4961
0.255,258.231,250,-1.5
0.256,259.073,250.787,-1.5079
0.257,259.668,251.575,-1.5157
0.257,260.516,251.969,-1.5197
0.258,261.256,252.756,-1.5276
0.259,261.623,253.543,-1.5354
0.259,262.665,253.937,-1.5394
0.26,263.377,254.724,-1.5472
0.261,263.836,255.512,-1.5551
0.261,264.68,255.906,-1.5591
0.262,265.332,256.693,-1.5669
0.263,265.829,257.48,-1.5748
0.263,266.699,257.874,-1.5787
0.264,267.331,258.662,-1.5866
0.265,267.858,259.449,-1.5945
0.265,268.658,259.843,-1.5984
0.266,269.302,260.63,-1.6063
0.267,269.806,261.024,-1.6102
0.267,270.838,261.811,-1.6181
0.268,271.323,262.599,-1.626
0.269,271.924,262.992,-1.6299
0.269,272.899,263.78,-1.6378
0.27,273.415,264.567,-1.6457
0.271,274.112,265.354,-1.6535
0.271,274.874,265.748,-1.6575
0.272,275.414,266.536,-1.6654
0.273,276.105,267.323,-1.6732
0.273,276.949,267.717,-1.6772
0.274,277.547,268.504,-1.685
0.275,277.974,268.898,-1.689
0.275,279.01,269.685,-1.6969
0.276,279.66,270.473,-1.7047
0.277,280.237,270.866,-1.7087
0.277,281.137,271.654,-1.7165
0.278,281.704,272.441,-1.7244
0.279,282.278,273.228,-1.7323
0.279,283.037,273.622,-1.7362
0.28,283.869,274.41,-1.7441
0.281,284.531,275.197,-1.752
0.281,285.315,275.591,-1.7559
0.282,286.098,276.378,-1.7638
0.283,286.469,277.165,-1.7717
0.283,287.37,277.559,-1.7756
0.284,288.046,278.347,-1.7835
0.285,288.476,279.134,-1.7913
0.285,289.495,279.528,-1.7953
0.286,289.939,280.315,-1.8032
0.287,290.628,281.102,-1.811
0.287,291.432,281.496,-1.815
0.288,292.022,282.284,-1.8228
0.289,292.623,283.071,-1.8307
0.289,293.476,283.465,-1.8346
0.29,294.144,284.252,-1.8425
0.291,294.618,284.646,-1.8465
0.291,295.544,285.433,-1.8543
0.292,296.086,286.221,-1.8622
0.293,296.778,286.614,-1.8661
0.293,297.606,287.402,-1.874
0.294,297.986,288.189,-1.8819
0.295,298.736,288.583,-1.8858
0.295,299.553,289.37,-1.8937
0.296,300.065,290.158,-1.9016
0.297,300.889,290.551,-1.9055
0.297,301.61,291.339,-1.9134
0.298,302.062,292.126,-1.9213
0.299,302.74,292.52,-1.9252
0.299,303.662,293.307,-1.9331
0.3,304.133,294.095,-1.9409
0.301,304.912,294.488,-1.9449
0.301,305.808,295.276,-1.9528
0.302,306.244,296.063,-1.9606
0.303,307.088,296.457,-1.9646
0.303,307.851,297.244,-1.9724
0.304,308.372,298.032,-1.9803
0.305,309.08,298.819,-1.9882
0.305,309.912,299.213,-1.9921
0.306,310.783,300,-2
0.307,311.33,300.788,-2.0079
0.307,311.964,301.575,-2.0157
0.308,312.711,301.969,-2.0197
0.309,313.646,302.756,-2.0276
0.309,314.335,303.543,-2.0354
0.31,314.876,304.331,-2.0433
0.311,315.735,305.118,-2.0512
0.311,316.519,305.512,-2.0551
0.312,317.465,306.299,-2.063
0.313,318.131,307.087,-2.0709
0.313,318.837,307.874,-2.0787
0.314,319.282,308.662,-2.0866
0.315,320.113,309.055,-2.0906
0.315,320.913,309.843,-2.0984
0.316,321.668,310.63,-2.1063
0.317,322.195,311.417,-2.1142
0.317,322.941,311.811,-2.1181
0.318,323.865,312.599,-2.126
0.319,324.287,313.386,-2.1339
0.319,325.098,313.78,-2.1378
0.32,325.927,314.567,-2.1457
0.321,326.441,315.354,-2.1535
0.321,327.211,315.748,-2.1575
0.322,328.028,316.536,-2.1654
0.323,328.511,317.323,-2.1732
0.323,329.228,317.717,-2.1772
0.324,330.118,318.504,-2.185
0.325,330.717,319.291,-2.1929
0.325,331.474,319.685,-2.1969
0.326,332.306,320.473,-2.2047
0.327,332.744,321.26,-2.2126
0.327,333.81,321.654,-2.2165
0.328,334.448,322.441,-2.2244
0.329,334.916,323.228,-2.2323
0.329,335.913,323.622,-2.2362
0.33,336.585,324.41,-2.2441
0.331,337.133,325.197,-2.252
0.331,337.967,325.591,-2.2559
0.332,338.743,326.378,-2.2638
0.333,339.34,327.165,-2.2717
0.333,340.28,327.559,-2.2756
0.334,340.934,328.347,-2.2835
0.335,341.392,328.74,-2.2874
0.335,342.484,329.528,-2.2953
0.336,343.009,330.315,-2.3032
0.337,343.649,330.709,-2.3071
0.337,344.746,331.496,-2.315
0.338,345.217,332.284,-2.3228
0.339,345.93,332.677,-2.3268
0.339,346.804,333.465,-2.3346
0.34,347.451,334.252,-2.3425
0.341,348.175,335.039,-2.3504
0.341,349.037,335.433,-2.3543
0.342,349.768,336.221,-2.3622
0.343,350.26,337.008,-2.3701
0.343,351.275,337.402,-2.374
0.344,352.057,338.189,-2.3819
0.345,352.583,338.977,-2.3898
0.345,353.563,338.977,-2.3898
0.346,354.718,340.158,-2.4016
0.347,355.273,340.945,-2.4095
0.347,355.952,341.339,-2.4134
0.348,356.816,342.126,-2.4213
0.349,357.414,342.914,-2.4291
0.349,358.28,343.307,-2.4331
0.35,359.003,344.095,-2.4409
0.351,359.415,344.882,-2.4488
0.351,360.448,345.276,-2.4528
0.352,361.152,346.063,-2.4606
0.353,361.696,346.851,-2.4685
0.353,362.671,347.244,-2.4724
0.354,363.181,348.032,-2.4803
0.355,363.876,348.425,-2.4843
0.355,364.801,349.213,-2.4921
0.356,365.355,350,-2.5
0.357,366.077,350.394,-2.5039
0.357,366.961,351.181,-2.5118
0.358,367.424,351.969,-2.5197
0.359,368.195,352.362,-2.5236
0.359,369.041,353.15,-2.5315
0.36,369.621,353.937,-2.5394
0.361,370.433,354.331,-2.5433
0.361,371.245,355.118,-2.5512
0.362,371.583,355.906,-2.5591
0.363,372.572,356.299,-2.563
0.363,373.345,357.087,-2.5709
0.364,373.863,357.874,-2.5787
0.365,374.894,358.268,-2.5827
0.365,375.6,359.055,-2.5906
0.366,376.154,359.843,-2.5984
0.367,377.021,360.236,-2.6024
0.367,377.872,361.024,-2.6102
0.368,378.474,361.811,-2.6181
0.369,379.426,362.205,-2.622
0.369,380.38,362.992,-2.6299
0.37,380.832,363.78,-2.6378
0.371,381.676,364.173,-2.6417
0.371,382.675,364.961,-2.6496
0.372,383.583,365.748,-2.6575
0.373,384.37,366.536,-2.6654
0.373,385.167,366.929,-2.6693
0.374,386.338,367.717,-2.6772
0.375,387.248,368.504,-2.685
0.375,388.14,369.291,-2.6929
0.376,388.82,370.079,-2.7008
0.377,389.963,370.473,-2.7047
0.377,390.892,371.26,-2.7126
0.378,392.107,372.047,-2.7205
0.379,393.039,372.835,-2.7283
0.379,393.954,373.622,-2.7362
0.38,394.784,374.41,-2.7441
0.381,395.764,374.803,-2.748
0.381,396.857,375.591,-2.7559
0.382,397.516,376.378,-2.7638
0.383,398.385,376.772,-2.7677
0.383,399.453,377.559,-2.7756
0.384,400.369,378.347,-2.7835
0.385,401.108,379.134,-2.7913
0.385,402.099,379.528,-2.7953
0.386,403.113,380.315,-2.8032
0.387,403.696,381.103,-2.811
0.387,404.88,381.496,-2.815
0.388,405.486,382.284,-2.8228
0.389,406.33,382.677,-2.8268
0.389,407.54,383.465,-2.8346
0.39,408.141,384.252,-2.8425
0.391,409.204,384.646,-2.8465
0.391,410.249,385.433,-2.8543
0.392,410.847,386.221,-2.8622
0.393,411.965,386.614,-2.8661
0.393,412.836,387.402,-2.874
0.394,413.653,388.189,-2.8819
0.395,414.715,388.583,-2.8858
0.395,415.726,389.37,-2.8937
0.396,416.409,390.158,-2.9016
0.397,417.514,390.551,-2.9055
0.397,418.519,391.339,-2.9134
0.398,419.138,392.126,-2.9213
0.399,420.33,392.52,-2.9252
0.399,421.239,393.307,-2.9331
0.4,422,394.095,-2.9409
0.401,423.305,394.488,-2.9449
0.401,424.013,395.276,-2.9528
0.402,424.822,395.669,-2.9567
0.403,425.948,396.457,-2.9646
0.403,426.754,397.244,-2.9724
0.404,427.712,398.032,-2.9803
0.405,428.763,398.425,-2.9843
0.405,429.582,399.213,-2.9921
0.406,430.414,399.606,-2.9961
0.407,431.646,400.394,-3.0039
0.407,432.599,401.181,-3.0118
0.408,433.356,401.575,-3.0157
0.409,434.699,402.362,-3.0236
0.409,435.485,403.15,-3.0315
0.41,436.337,403.937,-3.0394
0.411,437.37,404.331,-3.0433
0.411,438.39,405.118,-3.0512
0.412,439.337,405.906,-3.0591
0.413,440.81,406.299,-3.063
0.413,441.811,407.087,-3.0709
0.414,442.586,407.874,-3.0787
0.415,443.884,408.268,-3.0827
0.415,444.629,409.055,-3.0906
0.416,445.542,409.449,-3.0945
0.417,446.918,410.236,-3.1024
0.417,447.553,411.024,-3.1102
0.418,448.617,411.417,-3.1142
0.419,449.695,412.205,-3.122
0.419,450.571,412.992,-3.1299
0.42,451.666,413.386,-3.1339
0.421,452.719,414.173,-3.1417
0.421,453.391,414.961,-3.1496
0.422,454.409,415.355,-3.1535
0.423,455.623,416.142,-3.1614
0.423,456.456,416.929,-3.1693
0.424,457.594,417.323,-3.1732
0.425,458.626,418.11,-3.1811
0.425,459.341,418.898,-3.189
0.426,460.713,419.292,-3.1929
0.427,461.573,420.079,-3.2008
0.427,462.48,420.473,-3.2047
0.428,463.896,421.26,-3.2126
0.429,464.507,422.047,-3.2205
0.429,465.752,422.441,-3.2244
0.43,466.887,423.229,-3.2323
0.431,467.669,424.016,-3.2402
0.431,468.861,424.41,-3.2441
0.432,469.939,425.197,-3.252
0.433,470.645,425.984,-3.2598
0.433,471.841,426.378,-3.2638
0.434,473.189,427.166,-3.2717
0.435,474.082,427.953,-3.2795
0.435,475.023,428.347,-3.2835
0.436,476.364,429.134,-3.2913
0.437,477.311,429.921,-3.2992
0.437,478.421,430.709,-3.3071
0.438,479.549,431.103,-3.311
0.439,480.994,431.89,-3.3189
0.439,482.083,432.677,-3.3268
0.44,482.922,433.465,-3.3346
0.441,484.226,434.252,-3.3425
0.441,485.414,434.646,-3.3465
0.442,486.865,435.433,-3.3543
0.443,487.872,436.221,-3.3622
0.443,488.946,437.008,-3.3701
0.444,489.952,437.795,-3.378
0.445,491.514,438.189,-3.3819
0.445,492.632,438.977,-3.3898
0.446,493.844,439.764,-3.3976
0.447,494.938,440.551,-3.4055
0.447,495.893,441.339,-3.4134
0.448,497.23,441.732,-3.4173
0.449,498.327,442.52,-3.4252
0.449,499.258,443.307,-3.4331
0.45,500.446,443.701,-3.437
0.451,501.685,444.488,-3.4449
0.451,502.728,445.276,-3.4528
0.452,503.664,445.669,-3.4567
0.453,504.965,446.457,-3.4646
0.453,505.597,447.244,-3.4724
0.454,507.06,447.638,-3.4764
0.455,507.933,448.425,-3.4843
0.455,509.175,448.819,-3.4882
0.456,510.464,449.606,-3.4961
0.457,511.228,450.394,-3.5039
0.457,512.539,450.788,-3.5079
0.458,513.744,451.575,-3.5157
0.459,514.606,452.362,-3.5236
0.459,515.937,452.756,-3.5276
0.46,517.068,453.543,-3.5354
0.461,517.998,454.331,-3.5433
0.461,519.173,454.725,-3.5472
0.462,520.574,455.512,-3.5551
0.463,521.392,456.299,-3.563
0.463,522.722,456.693,-3.5669
0.464,523.855,457.481,-3.5748
0.465,524.798,458.268,-3.5827
0.465,526.281,458.662,-3.5866
0.466,527.404,459.449,-3.5945
0.467,528.35,459.843,-3.5984
0.467,529.831,460.63,-3.6063
0.468,530.71,461.418,-3.6142
0.469,531.883,461.811,-3.6181
0.469,533.158,462.599,-3.626
0.47,534.27,463.386,-3.6339
0.471,535.504,463.78,-3.6378
0.471,536.689,464.567,-3.6457
0.472,537.661,465.355,-3.6535
0.473,538.925,465.748,-3.6575
0.473,540.339,466.536,-3.6654
0.474,541.351,467.323,-3.6732
0.475,542.461,467.717,-3.6772
0.475,544.002,468.504,-3.685
0.476,544.982,469.292,-3.6929
0.477,546.078,469.685,-3.6969
0.477,547.468,470.473,-3.7047
0.478,548.472,471.26,-3.7126
0.479,549.701,472.047,-3.7205
0.479,550.995,472.441,-3.7244
0.48,552.207,473.229,-3.7323
0.481,553.105,474.016,-3.7402
0.481,554.597,474.41,-3.7441
0.482,555.679,475.197,-3.752
0.483,556.747,475.591,-3.7559
0.483,558.244,476.378,-3.7638
0.484,559.191,477.166,-3.7717
0.485,560.435,477.559,-3.7756
0.485,562.008,478.347,-3.7835
0.486,563.255,479.134,-3.7913
0.487,564.61,479.528,-3.7953
0.487,565.851,480.315,-3.8032
0.488,566.777,481.103,-3.811
0.489,568.011,481.496,-3.815
0.489,569.224,482.284,-3.8228
0.49,570.361,483.071,-3.8307
0.491,571.648,483.465,-3.8346
0.491,572.879,484.252,-3.8425
0.492,573.883,485.04,-3.8504
0.493,575.41,485.433,-3.8543
0.493,576.491,486.221,-3.8622
0.494,577.568,486.614,-3.8661
0.495,579.1,487.402,-3.874
0.495,580.085,488.189,-3.8819
0.496,581.357,488.583,-3.8858
0.497,582.74,489.37,-3.8937
0.497,583.657,490.158,-3.9016
0.498,585.103,490.945,-3.9095
0.499,586.387,491.339,-3.9134
0.499,587.436,492.126,-3.9213
0.5,588.55,492.52,-3.9252
0.501,590.224,493.307,-3.9331
0.501,591.237,494.095,-3.9409
0.502,592.347,494.882,-3.9488
0.503,594.005,495.276,-3.9528
0.503,595.29,496.063,-3.9606
0.504,596.375,496.851,-3.9685
0.505,597.489,497.638,-3.9764
0.505,599.066,498.032,-3.9803
0.506,600.539,498.819,-3.9882
0.507,601.563,499.607,-3.9961
0.507,603.182,500.394,-4.0039
0.508,604.412,501.181,-4.0118
0.509,605.921,501.575,-4.0158
0.509,607.327,502.362,-4.0236
0.51,608.742,503.15,-4.0315
0.511,609.767,503.937,-4.0394
0.511,611.244,504.725,-4.0472
0.512,612.504,505.118,-4.0512
0.513,614.075,505.906,-4.0591
0.513,615.271,506.693,-4.0669
0.514,616.48,507.481,-4.0748
0.515,618.093,507.874,-4.0787
0.515,619.265,508.662,-4.0866
0.516,620.522,509.449,-4.0945
0.517,621.621,509.843,-4.0984
0.517,623.207,510.63,-4.1063
0.518,624.273,511.418,-4.1142
0.519,625.372,511.811,-4.1181
0.519,626.603,512.599,-4.126
0.52,627.587,512.992,-4.1299
0.521,629.107,513.78,-4.1378
0.521,630.174,514.567,-4.1457
0.522,631.534,514.961,-4.1496
0.523,633.06,515.748,-4.1575
0.523,633.967,516.536,-4.1654
0.524,635.434,516.929,-4.1693
0.525,636.613,517.717,-4.1772
0.525,637.742,518.504,-4.185
0.526,639.313,518.898,-4.189
0.527,640.499,519.685,-4.1969
0.527,641.661,520.079,-4.2008
0.528,643.112,520.866,-4.2087
0.529,644.252,521.654,-4.2165
0.529,645.573,522.441,-4.2244
0.53,646.988,522.835,-4.2283
0.531,648.127,523.622,-4.2362
0.531,649.336,524.016,-4.2402
0.532,650.989,524.803,-4.248
0.533,652.119,525.591,-4.2559
0.533,653.225,525.984,-4.2598
0.534,654.929,526.772,-4.2677
0.535,655.862,527.559,-4.2756
0.535,657.244,527.953,-4.2795
0.536,658.576,528.74,-4.2874
0.537,659.69,529.528,-4.2953
0.537,661.146,529.921,-4.2992
0.538,662.427,530.709,-4.3071
0.539,663.532,531.496,-4.315
0.539,664.901,531.89,-4.3189
0.54,666.411,532.677,-4.3268
0.541,667.473,533.465,-4.3346
0.541,668.77,533.859,-4.3386
0.542,670.332,534.646,-4.3465
0.543,671.296,535.433,-4.3543
0.543,672.74,535.827,-4.3583
0.544,674.246,536.614,-4.3661
0.545,675.216,537.402,-4.374
0.545,676.738,537.796,-4.378
0.546,678.097,538.583,-4.3858
0.547,679.153,539.37,-4.3937
0.547,680.406,539.764,-4.3976
0.548,681.837,540.551,-4.4055
0.549,682.928,541.339,-4.4134
0.549,684.359,541.733,-4.4173
0.55,685.889,542.52,-4.4252
0.551,686.714,543.307,-4.4331
0.551,688.353,543.701,-4.437
0.552,689.566,544.488,-4.4449
0.553,690.617,545.276,-4.4528
0.553,692.281,545.67,-4.4567
0.554,693.476,546.457,-4.4646
0.555,695.519,547.244,-4.4724
0.555,696.605,547.638,-4.4764
0.556,697.625,548.425,-4.4843
0.557,699.071,548.819,-4.4882
0.557,700.334,549.607,-4.4961
0.558,701.466,550.394,-4.5039
0.559,702.713,550.788,-4.5079
0.559,704.092,551.575,-4.5158
0.56,705.272,552.362,-4.5236
0.561,706.678,552.756,-4.5276
0.561,708.029,553.544,-4.5354
0.562,709.134,553.937,-4.5394
0.563,710.84,554.725,-4.5472
0.563,711.777,555.512,-4.5551
0.564,713.128,555.906,-4.5591
0.565,714.805,556.693,-4.5669
0.565,715.808,557.481,-4.5748
0.566,717.177,557.874,-4.5787
0.567,718.554,558.662,-4.5866
0.567,719.96,559.449,-4.5945
0.568,721.15,560.236,-4.6024
0.569,722.595,560.63,-4.6063
0.569,724.292,561.418,-4.6142
0.57,725.417,562.205,-4.622
0.571,726.864,562.992,-4.6299
0.571,728.238,563.386,-4.6339
0.572,729.898,564.173,-4.6417
0.573,731.048,564.961,-4.6496
0.573,732.426,565.748,-4.6575
0.574,734.103,566.536,-4.6654
0.575,735.509,566.929,-4.6693
0.575,737.095,567.717,-4.6772
0.576,738.198,568.504,-4.685
0.577,739.775,569.292,-4.6929
0.577,741.1,570.079,-4.7008
0.578,742.787,570.473,-4.7047
0.579,744.151,571.26,-4.7126
0.579,745.255,572.047,-4.7205
0.58,746.805,572.441,-4.7244
0.581,748.167,573.229,-4.7323
0.581,749.472,574.016,-4.7402
0.582,750.645,574.41,-4.7441
0.583,752.39,575.197,-4.752
0.583,753.634,575.985,-4.7598
0.584,754.803,576.772,-4.7677
0.585,756.39,577.166,-4.7717
0.585,757.474,577.953,-4.7795
0.586,758.761,578.347,-4.7835
0.587,760.215,579.134,-4.7913
0.587,761.093,579.922,-4.7992
0.588,762.777,580.315,-4.8032
0.589,764.163,581.103,-4.811
0.589,765.256,581.89,-4.8189
0.59,766.864,582.284,-4.8228
0.591,767.865,583.071,-4.8307
0.591,769.332,583.465,-4.8346
0.592,770.692,584.252,-4.8425
0.593,771.947,585.04,-4.8504
0.593,773.302,585.433,-4.8543
0.594,774.801,586.221,-4.8622
0.595,775.951,587.008,-4.8701
0.595,777.416,587.402,-4.874
0.596,778.406,588.189,-4.8819
0.597,779.799,588.977,-4.8898
0.597,781.483,589.37,-4.8937
0.598,782.609,590.158,-4.9016
0.599,783.908,590.551,-4.9055
0.599,785.4,591.339,-4.9134
0.6,786.399,592.126,-4.9213
0.601,788.024,592.52,-4.9252
0.601,789.374,593.307,-4.9331
0.602,790.47,594.095,-4.9409
0.603,792.136,594.488,-4.9449
0.603,793.263,595.276,-4.9528
0.604,794.595,595.67,-4.9567
0.605,796.074,596.457,-4.9646
0.605,797.371,597.244,-4.9724
0.606,798.764,597.638,-4.9764
0.607,800.23,598.425,-4.9843
0.607,801.455,599.213,-4.9921
0.608,802.683,599.607,-4.9961
0.609,804.323,600.394,-5.0039
0.609,805.576,601.181,-5.0118
0.61,806.867,601.575,-5.0158
0.611,808.584,602.362,-5.0236
0.611,809.57,603.15,-5.0315
0.612,811.102,603.544,-5.0354
0.613,812.544,604.331,-5.0433
0.613,813.585,605.118,-5.0512
0.614,815.324,605.512,-5.0551
0.615,816.553,606.299,-5.063
0.615,817.811,607.087,-5.0709
0.616,819.382,607.481,-5.0748
0.617,820.617,608.268,-5.0827
0.617,821.966,608.662,-5.0866
0.618,823.499,609.449,-5.0945
0.619,824.698,610.236,-5.1024
0.619,826.01,610.63,-5.1063
0.62,827.599,611.418,-5.1142
0.621,828.65,612.205,-5.1221
0.621,830.203,612.599,-5.126
0.622,831.6,613.386,-5.1339
0.623,832.739,614.174,-5.1417
0.623,834.367,614.567,-5.1457
0.624,835.616,615.355,-5.1535
0.625,836.846,615.748,-5.1575
0.625,838.55,616.536,-5.1654
0.626,839.622,617.323,-5.1732
0.627,841.178,617.717,-5.1772
0.627,842.512,618.504,-5.185
0.628,843.604,619.292,-5.1929
0.629,845.335,619.685,-5.1969
0.629,846.59,620.473,-5.2047
0.63,847.775,620.866,-5.2087
0.631,849.474,621.654,-5.2165
0.631,850.661,622.441,-5.2244
0.632,851.951,622.835,-5.2283
0.633,853.637,623.622,-5.2362
0.633,854.97,624.41,-5.2441
0.634,856.271,625.197,-5.252
0.635,858.009,625.591,-5.2559
0.635,859.46,626.378,-5.2638
0.636,860.88,627.166,-5.2717
0.637,862.262,627.953,-5.2795
0.637,863.908,628.347,-5.2835
0.638,865.364,629.134,-5.2913
0.639,866.52,629.922,-5.2992
0.639,868.119,630.315,-5.3032
0.64,869.819,631.103,-5.311
0.641,871.658,631.89,-5.3189
0.641,873.087,632.677,-5.3268
0.642,874.486,633.465,-5.3346
0.643,876.586,634.252,-5.3425
0.643,878.168,634.646,-5.3465
0.644,879.879,635.433,-5.3543
0.645,881.439,636.221,-5.3622
0.645,882.869,637.008,-5.3701
0.646,884.043,637.796,-5.378
0.647,885.796,638.189,-5.3819
0.647,887.234,638.977,-5.3898
0.648,888.414,639.764,-5.3976
0.649,889.945,640.158,-5.4016
0.649,891.487,640.945,-5.4095
0.65,892.797,641.733,-5.4173
0.651,894.018,642.126,-5.4213
0.651,895.689,642.914,-5.4291
0.652,896.602,643.701,-5.437
0.653,898.231,644.095,-5.4409
0.653,899.458,644.882,-5.4488
0.654,900.799,645.276,-5.4528
0.655,902.466,646.063,-5.4606
0.655,903.551,646.851,-5.4685
0.656,905.151,647.244,-5.4724
0.657,906.498,648.032,-5.4803
0.657,907.725,648.425,-5.4843
0.658,909.363,649.213,-5.4921
0.659,910.487,650,-5.5
0.659,912.008,650.394,-5.5039
0.66,913.564,651.181,-5.5118
0.661,914.592,651.969,-5.5197
0.661,916.261,652.363,-5.5236
0.662,917.562,653.15,-5.5315
0.663,918.775,653.544,-5.5354
0.663,920.576,654.331,-5.5433
0.664,921.753,655.118,-5.5512
0.665,923.192,655.512,-5.5551
0.665,924.684,656.3,-5.563
0.666,925.815,657.087,-5.5709
0.667,927.542,657.481,-5.5748
0.667,928.805,658.268,-5.5827
0.668,930.044,658.662,-5.5866
0.669,931.666,659.449,-5.5945
0.669,932.849,660.237,-5.6024
0.67,934.32,661.024,-5.6102
0.671,935.974,661.418,-5.6142
0.671,937.204,662.205,-5.6221
0.672,938.541,662.599,-5.626
0.673,940.226,663.386,-5.6339
0.673,941.481,664.174,-5.6417
0.674,942.888,664.567,-5.6457
0.675,944.549,665.355,-5.6535
0.675,945.682,666.142,-5.6614
0.676,947.422,666.536,-5.6654
0.677,948.826,667.323,-5.6732
0.677,949.956,668.111,-5.6811
0.678,951.703,668.504,-5.685
0.679,952.964,669.292,-5.6929
0.679,954.281,670.079,-5.7008
0.68,955.791,670.473,-5.7047
0.681,957.226,671.26,-5.7126
0.681,958.504,671.654,-5.7165
0.682,960.168,672.441,-5.7244
0.683,961.426,673.229,-5.7323
0.683,962.891,673.622,-5.7362
0.684,964.527,674.41,-5.7441
0.685,965.667,675.197,-5.752
0.685,967.122,675.591,-5.7559
0.686,968.876,676.378,-5.7638
0.687,970.02,677.166,-5.7717
0.687,971.596,677.559,-5.7756
0.688,972.914,678.347,-5.7835
0.689,974.163,678.74,-5.7874
0.689,975.845,679.528,-5.7953
0.69,977.014,680.315,-5.8032
0.691,978.541,680.709,-5.8071
0.691,980.143,681.496,-5.815
0.692,981.34,682.284,-5.8228
0.693,982.986,682.677,-5.8268
0.693,984.422,683.465,-5.8346
0.694,985.607,684.252,-5.8425
0.695,987.306,684.646,-5.8465
0.695,988.681,685.433,-5.8543
0.696,989.983,686.221,-5.8622
0.697,991.705,686.614,-5.8661
0.697,993.039,687.402,-5.874
0.698,994.346,688.189,-5.8819
0.699,996.146,688.583,-5.8858
0.699,997.543,689.37,-5.8937
0.7,998.673,690.158,-5.9016
0.701,1000.237,690.551,-5.9055
0.701,1000.516,690.552,-5.9055